Workbook

Sheet Cover
B2: TITAN COMPANY LIMITED
B3: Institutional Financial Statement & Valuation Model | Ind AS Architecture
B5: Filing Basis | C5: Consolidated Financial Statements | Fiscal Year Ending 31 March
B6: Reporting Currency | C6: Indian Rupees (INR) in Crore
B7: Historical Horizon | C7: FY 2021-22A to FY 2025-26A (Audited Annual Reports)
B8: Forecast Horizon | C8: FY 2026-27E to FY 2030-31E (Driver-Based Projections)
B9: Fade Horizon | C9: FY 2031-32E to FY 2035-36E (5-Year Value-Driver Fade Period in DCF)
B10: Active Scenario | C10: =Inputs!$C$6 -> Base
B11: Workbook Audit Status | C11: =Checks!$C$32 -> ALL CHECKS PASSED
B12: Valuation Methodology | C12: Unlevered DCF (WACC, CAPM, Gordon Growth & Exit EV/EBITDA Multiples)
B14: WORKBOOK STRUCTURE & NAVIGATION
B15: Summary | C15: Executive dashboard, valuation summary, key credit metrics, and visual charts
B16: Inputs | C16: Assumption drivers, scenario selector (Bear/Base/Bull), WACC and valuation parameters
B17: IS | C17: Consolidated Statement of Profit and Loss (audited historicals and projected drivers)
B18: BS | C18: Consolidated Balance Sheet (self-balancing, zero artificial plug, cash sweep)
B19: CF | C19: Consolidated Statement of Cash Flows (Ind AS indirect method with Ind AS 116 retail leases)
B20: Schedules | C20: Supporting schedules: Working Capital, Capex/FA, Debt Revolver, Leases, Equity, Ratios
B21: Earnings_Quality | C21: Forensic accounting suite: Sloan accruals, DuPont 3-stage, CCC, Altman Z''-score
B22: DCF | C22: Discounted Cash Flow: 10-year UFCF, CAPM WACC, terminal value, equity bridge
B23: Sensitivity | C23: 2D live formula sensitivity tables: WACC vs Terminal Growth g, WACC vs Exit Multiple
B24: Scenarios | C24: Scenario comparative matrix (Bear vs Base vs Bull)
B25: Checks | C25: Automated system audit suite testing internal mathematical identities
B26: PowerBI_Export | C26: Flat unpivoted dataset with standardized headers for Power BI / Python ingest
... B28: Notes | C28: Detailed documentation of methodology, calibration notes, and Ind AS accounting policies

Sheet Summary
A1: TITAN COMPANY LIMITED: EXECUTIVE VALUATION DASHBOARD
A2: Integrated Financial Model | FY22A-FY26A Audited Actuals, FY27E-FY31E Projections | INR Crore
A4: Active Model Scenario | C4: =Inputs!$C$6 -> Base | E4: Model Methodology & Principles
A5: Workbook Integrity Status | C5: =Checks!$C$32 -> ALL CHECKS PASSED | E5: Operating EBITDA/EBIT strictly exclude non-operating treasury income. Net Debt incorporates Gold on Loan and Ind AS 116 Leases.
A6: Current Market Price (CMP, INR) | C6: =Inputs!$C$9 -> 4798.5
A7: Weighted Average Cost of Capital (WACC) | C7: =DCF!$C$15 -> 0.112695
A8: Perpetual Terminal Growth Rate (g) | C8: =Inputs!$C$18 -> 0.05
A9: DCF Target Value per Share (Gordon Growth, INR) | C9: =DCF!$C$62 -> 995.47082
A10: Gordon Growth DCF Upside / (Downside) | C10: =DCF!$C$64 -> -0.79254542
A11: Target Value per Share (Exit Multiple, INR) | C11: =DCF!$C$73 -> 2861.2805
A12: Exit Multiple Upside / (Downside) | C12: =DCF!$C$74 -> -0.40371355
A13: Enterprise Value (Gordon Growth, INR cr) | C13: =DCF!$C$52 -> 97505.899
A14: PV of Terminal Value % Enterprise Value | C14: =DCF!$C$77 -> 0.68507887
A17: KPI Overview (INR crore unless stated) | B17: Unit | C17: FY22A | D17: FY23A | E17: FY24A | F17: FY25A | G17: FY26A | H17: FY27E | I17: FY28E | J17: FY29E | K17: FY30E | L17: FY31E
A18: Revenue from operations | B18: cr | C18: =IS!C5 -> 28799 | D18: =IS!D5 -> 40575 | E18: =IS!E5 -> 51084 | F18: =IS!F5 -> 60456 | G18: =IS!G5 -> 87584 | H18: =IS!H5 -> 103349.12 | I18: =IS!I5 -> 118851.49 | J18: =IS!J5 -> 134302.18 | ... L18: =IS!L5 -> 166964.47
A19: y/y revenue growth rate | B19: % | D19: =IS!D6 -> 0.40890309 | E19: =IS!E6 -> 0.25900185 | F19: =IS!F6 -> 0.18346253 | G19: =IS!G6 -> 0.44872304 | H19: =IS!H6 -> 0.18 | I19: =IS!I6 -> 0.15 | J19: =IS!J6 -> 0.13 | K19: =IS!K6 -> 0.12 | L19: =IS!L6 -> 0.11
A20: Gross margin | B20: % | C20: =IS!C9 -> 0.2485503 | D20: =IS!D9 -> 0.25187924 | E20: =IS!E9 -> 0.2280949 | F20: =IS!F9 -> 0.21503242 | G20: =IS!G9 -> 0.19726206 | H20: =IS!H9 -> 0.197 | I20: =IS!I9 -> 0.198 | J20: =IS!J9 -> 0.199 | ... L20: =IS!L9 -> 0.2
A21: Operating EBITDA | B21: cr | C21: =IS!C14 -> 3341 | D21: =IS!D14 -> 4879 | E21: =IS!E14 -> 5292 | F21: =IS!F14 -> 5694 | G21: =IS!G14 -> 8355 | H21: =IS!H14 -> 9921.5155 | I21: =IS!I14 -> 11647.446 | J21: =IS!J14 -> 13430.218 | ... L21: =IS!L14 -> 17030.376
A22: EBITDA margin | B22: % | C22: =IS!C15 -> 0.11601097 | D22: =IS!D15 -> 0.12024646 | E22: =IS!E15 -> 0.10359408 | F22: =IS!F15 -> 0.0941842 | G22: =IS!G15 -> 0.095394136 | H22: =IS!H15 -> 0.096 | I22: =IS!I15 -> 0.098 | J22: =IS!J15 -> 0.1 | ... L22: =IS!L15 -> 0.102
A23: Operating EBIT | B23: cr | C23: =IS!C17 -> 2942 | D23: =IS!D17 -> 4438 | E23: =IS!E17 -> 4708 | F23: =IS!F17 -> 5001 | G23: =IS!G17 -> 7529 | H23: =IS!H17 -> 8785.9555 | I23: =IS!I17 -> 10291.254 | J23: =IS!J17 -> 11832.33 | ... L23: =IS!L17 -> 14898.547
A24: EBIT margin | B24: % | C24: =IS!C18 -> 0.10215632 | D24: =IS!D18 -> 0.1093777 | E24: =IS!E18 -> 0.092161929 | F24: =IS!F18 -> 0.082721318 | G24: =IS!G18 -> 0.08596319 | H24: =IS!H18 -> 0.085012388 | I24: =IS!I18 -> 0.086589189 | J24: =IS!J18 -> 0.088102289 | ... L24: =IS!L18 -> 0.089231843
A25: Profit After Tax (PAT) | B25: cr | C25: =IS!C27 -> 2198 | D25: =IS!D27 -> 3274 | E25: =IS!E27 -> 3496 | F25: =IS!F27 -> 3337 | G25: =IS!G27 -> 5073 | H25: =IS!H27 -> 5865.4261 | I25: =IS!I27 -> 6934.2101 | J25: =IS!J27 -> 8081.8267 | ... L25: =IS!L27 -> 10454.444
A26: PAT margin | B26: % | C26: =IS!C28 -> 0.076322095 | D26: =IS!D28 -> 0.08069008 | E26: =IS!E28 -> 0.068436301 | F26: =IS!F28 -> 0.055197168 | G26: =IS!G28 -> 0.057921538 | H26: =IS!H28 -> 0.056753518 | I26: =IS!I28 -> 0.058343486 | J26: =IS!J28 -> 0.060176437 | ... L26: =IS!L28 -> 0.06261478
A27: Basic EPS (INR) | B27: INR | C27: =IS!C31 -> 24.757828 | D27: =IS!D31 -> 36.877675 | E27: =IS!E31 -> 39.378238 | F27: =IS!F31 -> 37.587294 | G27: =IS!G31 -> 57.141248 | H27: =IS!H31 -> 66.066976 | I27: =IS!I31 -> 78.105543 | J27: =IS!J31 -> 91.032065 | ... L27: =IS!L31 -> 117.75674
A28: Cash flow from operations (CFO) | B28: cr | C28: =CF!C17 -> -724 | D28: =CF!D17 -> 1370 | E28: =CF!E17 -> 1695 | F28: =CF!F17 -> -541 | G28: =CF!G17 -> 5590 | H28: =CF!H17 -> 4433.9242 | I28: =CF!I17 -> 6352.1374 | J28: =CF!J17 -> 7764.5457 | ... L28: =CF!L17 -> 10312.795
A29: Capital expenditures | B29: cr | C29: =Schedules!C32 -> 224 | D29: =Schedules!D32 -> 432 | E29: =Schedules!E32 -> 691 | F29: =Schedules!F32 -> 494 | G29: =Schedules!G32 -> 902 | H29: =Schedules!H32 -> 1240.1894 | I29: =Schedules!I32 -> 1426.2179 | J29: =Schedules!J32 -> 1611.6262 | ... L29: =Schedules!L32 -> 2003.5737
A30: Free Cash Flow (FCF) | B30: cr | C30: =CF!C37 -> -948 | D30: =CF!D37 -> 938 | E30: =CF!E37 -> 1004 | F30: =CF!F37 -> -1035 | G30: =CF!G37 -> 4688 | H30: =CF!H37 -> 3193.7348 | I30: =CF!I37 -> 4925.9196 | J30: =CF!J37 -> 6152.9195 | ... L30: =CF!L37 -> 8309.2217
A31: Net debt (incl. GoL & Leases) | B31: cr | C31: =Schedules!C95 -> 5687 | D31: =Schedules!D95 -> 5860 | E31: =Schedules!E95 -> 12336 | F31: =Schedules!F95 -> 17856 | G31: =Schedules!G95 -> 26455 | H31: =Schedules!H95 -> 29025.681 | I31: =Schedules!I95 -> 30617.666 | J31: =Schedules!J95 -> 31412.3 | ... L31: =Schedules!L95 -> 31379.188
A32: Net debt / EBITDA | B32: x | C32: =Schedules!C96 -> 1.702185 | D32: =Schedules!D96 -> 1.2010658 | E32: =Schedules!E96 -> 2.3310658 | F32: =Schedules!F96 -> 3.1359326 | G32: =Schedules!G96 -> 3.1663674 | H32: =Schedules!H96 -> 2.9255289 | I32: =Schedules!I96 -> 2.6287021 | J32: =Schedules!J96 -> 2.338927 | ... L32: =Schedules!L96 -> 1.8425423
A33: Return on Equity (ROE) | B33: % | D33: =Schedules!D93 -> 0.3083298 | E33: =Schedules!E93 -> 0.32830915 | F33: =Schedules!F93 -> 0.31755246 | G33: =Schedules!G93 -> 0.37128115 | H33: =Schedules!H93 -> 0.32674907 | I33: =Schedules!I93 -> 0.30314827 | J33: =Schedules!J93 -> 0.28204826 | K33: =Schedules!K93 -> 0.26169625 | L33: =Schedules!L93 -> 0.24431241
A34: Return on Invested Capital (ROIC) | B34: % | D34: =Schedules!D94 -> 0.19932735 | E34: =Schedules!E94 -> 0.18029922 | F34: =Schedules!F94 -> 0.14372075 | G34: =Schedules!G94 -> 0.15678912 | H34: =Schedules!H94 -> 0.14344826 | I34: =Schedules!I94 -> 0.14569084 | J34: =Schedules!J94 -> 0.14793129 | K34: =Schedules!K94 -> 0.1488501 | L34: =Schedules!L94 -> 0.14953587
A35: Days Inventory Outstanding (DIO) | B35: days | C35: =Schedules!C8 -> 229.53121 | D35: =Schedules!D8 -> 199.41229 | E35: =Schedules!E8 -> 176.34447 | F35: =Schedules!F8 -> 216.77259 | G35: =Schedules!G8 -> 221.90102 | H35: =Schedules!H8 -> 220 | I35: =Schedules!I8 -> 220 | J35: =Schedules!J8 -> 220 | ... L35: =Schedules!L8 -> 220

Sheet Inputs
A1: ASSUMPTIONS & DYNAMIC SCENARIO CONTROL
A2: Institutional driver console. Blue = input | Black = formula | Green = link. Yellow fill = key decision cell.
A4: 1. GLOBAL CONTROLS & SCENARIO SWITCHES
A5: Active Scenario Selector (1 = Bear, 2 = Base, 3 = Bull) | C5: 2
A6: Active Scenario Label | C6: =CHOOSE($C$5,"Bear","Base","Bull") -> Base
A7: Gold-on-Loan Accounting Mode (1 = Operating, 2 = Debt-like) | C7: 1 | D7: =IF($C$7=1,"Operating: Netted in NWC, interest in EBIT, NOT in EV bridge","Debt-like: Excluded from NWC, DEDUCTED in EV bridge, interest in financing") -> Operating: Netted in NWC, interest in EBIT, NOT in EV bridge
A8: Valuation Date (Audited Balance Sheet Cutoff) | C8: 31-Mar-2026
A9: Current Market Price (INR per share) | C9: 4798.5 | D9: NSE Closing Price as of Sep-2026 (Kotak Neo/NSE)
A10: Diluted Shares Outstanding (crore) | C10: 88.78
A12: 2. VALUATION & CAPITAL STRUCTURE ASSUMPTIONS
A13: Risk-free rate (10-year Indian G-Sec) | C13: 0.065
A14: Equity risk premium (ERP) | C14: 0.06
A15: Equity beta | C15: 0.9
A16: Pre-tax marginal cost of debt (Kd) | C16: 0.075
A17: Target debt ratio (D / (D + E)) | C17: 0.1
A18: Terminal growth rate (nominal, INR) | C18: 0.05
A19: Terminal Return on New Invested Capital (RONIC) | C19: 0.2
A21: Exit EV/EBITDA Multiple Cross-Check | C21: Bear | D21: Base | E21: Bull | F21: Active Live
A22: Terminal EV / EBITDA Exit Multiple | C22: 20 | D22: 25 | E22: 30 | F22: =CHOOSE($C$5,C22,D22,E22) -> 25
A24: 3. OPERATIONAL SCENARIOS (FY27E - FY31E)
A25: Driver | Historical vs Projections | C25: FY22A | D25: FY23A | E25: FY24A | F25: FY25A | G25: FY26A | H25: FY27E | I25: FY28E | J25: FY29E | K25: FY30E | L25: FY31E
A26: Revenue growth (y/y) - ACTIVE | C26: =IS!C6 -> 0 | D26: =IS!D6 -> 0.40890309 | E26: =IS!E6 -> 0.25900185 | F26: =IS!F6 -> 0.18346253 | G26: =IS!G6 -> 0.44872304 | H26: =CHOOSE($C$5,H27,H28,H29) -> 0.18 | I26: =CHOOSE($C$5,I27,I28,I29) -> 0.15 | J26: =CHOOSE($C$5,J27,J28,J29) -> 0.13 | K26: =CHOOSE($C$5,K27,K28,K29) -> 0.12 | L26: =CHOOSE($C$5,L27,L28,L29) -> 0.11
A27: [Bear] | H27: 0.1 | I27: 0.08 | J27: 0.08 | K27: 0.07 | L27: 0.07
A28: [Base] | H28: 0.18 | I28: 0.15 | J28: 0.13 | K28: 0.12 | L28: 0.11
A29: [Bull] | H29: 0.22 | I29: 0.18 | J29: 0.16 | K29: 0.14 | L29: 0.13
A31: Gross margin (revenue less materials, purchases, inventory change) - ACTIVE | C31: =IS!C9 -> 0.2485503 | D31: =IS!D9 -> 0.25187924 | E31: =IS!E9 -> 0.2280949 | F31: =IS!F9 -> 0.21503242 | G31: =IS!G9 -> 0.19726206 | H31: =CHOOSE($C$5,H32,H33,H34) -> 0.197 | I31: =CHOOSE($C$5,I32,I33,I34) -> 0.198 | J31: =CHOOSE($C$5,J32,J33,J34) -> 0.199 | K31: =CHOOSE($C$5,K32,K33,K34) -> 0.2 | L31: =CHOOSE($C$5,L32,L33,L34) -> 0.2
A32: [Bear] | H32: 0.19 | I32: 0.189 | J32: 0.188 | K32: 0.187 | L32: 0.187
A33: [Base] | H33: 0.197 | I33: 0.198 | J33: 0.199 | K33: 0.2 | L33: 0.2
A34: [Bull] | H34: 0.2 | I34: 0.203 | J34: 0.206 | K34: 0.208 | L34: 0.21
A36: Employee cost % revenue - ACTIVE | C36: =IS!C11 -> 0.046841904 | D36: =IS!D11 -> 0.040591497 | E36: =IS!E11 -> 0.03648892 | F36: =IS!F11 -> 0.0356623 | G36: =IS!G11 -> 0.030610614 | H36: =CHOOSE($C$5,H37,H38,H39) -> 0.03 | I36: =CHOOSE($C$5,I37,I38,I39) -> 0.0295 | J36: =CHOOSE($C$5,J37,J38,J39) -> 0.029 | K36: =CHOOSE($C$5,K37,K38,K39) -> 0.029 | L36: =CHOOSE($C$5,L37,L38,L39) -> 0.0285
A37: [Bear] | H37: 0.031 | I37: 0.031 | J37: 0.031 | K37: 0.031 | L37: 0.031
A38: [Base] | H38: 0.03 | I38: 0.0295 | J38: 0.029 | K38: 0.029 | L38: 0.0285
A39: [Bull] | H39: 0.0295 | I39: 0.029 | J39: 0.0285 | K39: 0.028 | L39: 0.028
A41: Other expenses % revenue - ACTIVE | C41: =IS!C13 -> 0.08569742 | D41: =IS!D13 -> 0.091041282 | E41: =IS!E13 -> 0.088011902 | F41: =IS!F13 -> 0.08518592 | G41: =IS!G13 -> 0.071257307 | H41: =CHOOSE($C$5,H42,H43,H44) -> 0.071 | I41: =CHOOSE($C$5,I42,I43,I44) -> 0.0705 | J41: =CHOOSE($C$5,J42,J43,J44) -> 0.07 | K41: =CHOOSE($C$5,K42,K43,K44) -> 0.07 | L41: =CHOOSE($C$5,L42,L43,L44) -> 0.0695
A42: [Bear] | H42: 0.0725 | I42: 0.0725 | J42: 0.0725 | K42: 0.0725 | L42: 0.0725
A43: [Base] | H43: 0.071 | I43: 0.0705 | J43: 0.07 | K43: 0.07 | L43: 0.0695
A44: [Bull] | H44: 0.07 | I44: 0.0695 | J44: 0.069 | K44: 0.0685 | L44: 0.068
A46: Capex % revenue (PP&E + intangibles) - ACTIVE | C46: =Schedules!C30 -> 0.0077780478 | D46: =Schedules!D30 -> 0.01064695 | E46: =Schedules!E30 -> 0.01352674 | F46: =Schedules!F30 -> 0.008171232 | G46: =Schedules!G30 -> 0.010298685 | H46: =CHOOSE($C$5,H47,H48,H49) -> 0.012 | I46: =CHOOSE($C$5,I47,I48,I49) -> 0.012 | J46: =CHOOSE($C$5,J47,J48,J49) -> 0.012 | K46: =CHOOSE($C$5,K47,K48,K49) -> 0.012 | L46: =CHOOSE($C$5,L47,L48,L49) -> 0.012
A47: [Bear] | H47: 0.01 | I47: 0.01 | J47: 0.01 | K47: 0.01 | L47: 0.01
A48: [Base] | H48: 0.012 | I48: 0.012 | J48: 0.012 | K48: 0.012 | L48: 0.012
...

Sheet IS
A1: CONSOLIDATED STATEMENT OF PROFIT & LOSS
A2: Historical audited financials (FY22A-FY26A) & driver-based projections (FY27E-FY31E)
A4: Line Item (INR crore unless stated) | B4: Unit | C4: FY22A | D4: FY23A | E4: FY24A | F4: FY25A | G4: FY26A | H4: FY27E | I4: FY28E | J4: FY29E | K4: FY30E | L4: FY31E
A5: Revenue from operations | C5: =Hist_Data!C6 -> 28799 | D5: =Hist_Data!D6 -> 40575 | E5: =Hist_Data!E6 -> 51084 | F5: =Hist_Data!F6 -> 60456 | G5: =Hist_Data!G6 -> 87584 | H5: =G5*(1+H6) -> 103349.12 | I5: =H5*(1+I6) -> 118851.49 | J5: =I5*(1+J6) -> 134302.18 | K5: =J5*(1+K6) -> 150418.44 | L5: =K5*(1+L6) -> 166964.47
A6: y/y revenue growth rate | B6: % | D6: =D5/C5-1 -> 0.40890309 | E6: =E5/D5-1 -> 0.25900185 | F6: =F5/E5-1 -> 0.18346253 | G6: =G5/F5-1 -> 0.44872304 | H6: =Inputs!H26 -> 0.18 | I6: =Inputs!I26 -> 0.15 | J6: =Inputs!J26 -> 0.13 | K6: =Inputs!K26 -> 0.12 | L6: =Inputs!L26 -> 0.11
A7: Cost of goods sold (raw material, purchases, inventory change) | C7: =Hist_Data!C9+Hist_Data!C10+Hist_Data!C11 -> 21641 | D7: =Hist_Data!D9+Hist_Data!D10+Hist_Data!D11 -> 30355 | E7: =Hist_Data!E9+Hist_Data!E10+Hist_Data!E11 -> 39432 | F7: =Hist_Data!F9+Hist_Data!F10+Hist_Data!F11 -> 47456 | G7: =Hist_Data!G9+Hist_Data!G10+Hist_Data!G11 -> 70307 | H7: =H5*(1-H9) -> 82989.343 | I7: =I5*(1-I9) -> 95318.893 | J7: =J5*(1-J9) -> 107576.05 | K7: =K5*(1-K9) -> 120334.75 | L7: =L5*(1-L9) -> 133571.58
A8: Gross profit | C8: =C5-C7 -> 7158 | D8: =D5-D7 -> 10220 | E8: =E5-E7 -> 11652 | F8: =F5-F7 -> 13000 | G8: =G5-G7 -> 17277 | H8: =H5-H7 -> 20359.777 | I8: =I5-I7 -> 23532.595 | J8: =J5-J7 -> 26726.134 | ... L8: =L5-L7 -> 33392.894
A9: gross margin | B9: % | C9: =C8/C5 -> 0.2485503 | D9: =D8/D5 -> 0.25187924 | E9: =E8/E5 -> 0.2280949 | F9: =F8/F5 -> 0.21503242 | G9: =G8/G5 -> 0.19726206 | H9: =Inputs!H31 -> 0.197 | I9: =Inputs!I31 -> 0.198 | J9: =Inputs!J31 -> 0.199 | K9: =Inputs!K31 -> 0.2 | L9: =Inputs!L31 -> 0.2
A10: Employee benefits expense | C10: =Hist_Data!C12 -> 1349 | D10: =Hist_Data!D12 -> 1647 | E10: =Hist_Data!E12 -> 1864 | F10: =Hist_Data!F12 -> 2156 | G10: =Hist_Data!G12 -> 2681 | H10: =H5*H11 -> 3100.4736 | I10: =I5*I11 -> 3506.1189 | J10: =J5*J11 -> 3894.7633 | K10: =K5*K11 -> 4362.1349 | L10: =L5*L11 -> 4758.4875
A11: employee cost % revenue | B11: % | C11: =C10/C5 -> 0.046841904 | D11: =D10/D5 -> 0.040591497 | E11: =E10/E5 -> 0.03648892 | F11: =F10/F5 -> 0.0356623 | G11: =G10/G5 -> 0.030610614 | H11: =Inputs!H36 -> 0.03 | I11: =Inputs!I36 -> 0.0295 | J11: =Inputs!J36 -> 0.029 | K11: =Inputs!K36 -> 0.029 | L11: =Inputs!L36 -> 0.0285
A12: Other operating expenses | C12: =Hist_Data!C15 -> 2468 | D12: =Hist_Data!D15 -> 3694 | E12: =Hist_Data!E15 -> 4496 | F12: =Hist_Data!F15 -> 5150 | G12: =Hist_Data!G15 -> 6241 | H12: =H5*H13 -> 7337.7875 | I12: =I5*I13 -> 8379.0299 | J12: =J5*J13 -> 9401.1527 | K12: =K5*K13 -> 10529.291 | L12: =L5*L13 -> 11604.031
A13: other expenses % revenue | B13: % | C13: =C12/C5 -> 0.08569742 | D13: =D12/D5 -> 0.091041282 | E13: =E12/E5 -> 0.088011902 | F13: =F12/F5 -> 0.08518592 | G13: =G12/G5 -> 0.071257307 | H13: =Inputs!H41 -> 0.071 | I13: =Inputs!I41 -> 0.0705 | J13: =Inputs!J41 -> 0.07 | K13: =Inputs!K41 -> 0.07 | L13: =Inputs!L41 -> 0.0695
A14: Operating EBITDA (excl. other income) | C14: =C8-C10-C12 -> 3341 | D14: =D8-D10-D12 -> 4879 | E14: =E8-E10-E12 -> 5292 | F14: =F8-F10-F12 -> 5694 | G14: =G8-G10-G12 -> 8355 | H14: =H8-H10-H12 -> 9921.5155 | I14: =I8-I10-I12 -> 11647.446 | J14: =J8-J10-J12 -> 13430.218 | ... L14: =L8-L10-L12 -> 17030.376
A15: EBITDA margin | B15: % | C15: =C14/C5 -> 0.11601097 | D15: =D14/D5 -> 0.12024646 | E15: =E14/E5 -> 0.10359408 | F15: =F14/F5 -> 0.0941842 | G15: =G14/G5 -> 0.095394136 | H15: =H14/H5 -> 0.096 | I15: =I14/I5 -> 0.098 | J15: =J14/J5 -> 0.1 | ... L15: =L14/L5 -> 0.102
A16: Depreciation & amortisation | C16: =Hist_Data!C14 -> 399 | D16: =Hist_Data!D14 -> 441 | E16: =Hist_Data!E14 -> 584 | F16: =Hist_Data!F14 -> 693 | G16: =Hist_Data!G14 -> 826 | H16: =Schedules!H51 -> 1135.56 | I16: =Schedules!I51 -> 1356.1919 | J16: =Schedules!J51 -> 1597.8885 | K16: =Schedules!K51 -> 1856.5236 | L16: =Schedules!L51 -> 2131.8287
A17: Operating EBIT (operating profit) | C17: =C14-C16 -> 2942 | D17: =D14-D16 -> 4438 | E17: =E14-E16 -> 4708 | F17: =F14-F16 -> 5001 | G17: =G14-G16 -> 7529 | H17: =H14-H16 -> 8785.9555 | I17: =I14-I16 -> 10291.254 | J17: =J14-J16 -> 11832.33 | ... L17: =L14-L16 -> 14898.547
A18: EBIT margin | B18: % | C18: =C17/C5 -> 0.10215632 | D18: =D17/D5 -> 0.1093777 | E18: =E17/E5 -> 0.092161929 | F18: =F17/F5 -> 0.082721318 | G18: =G17/G5 -> 0.08596319 | H18: =H17/H5 -> 0.085012388 | I18: =I17/I5 -> 0.086589189 | J18: =J17/J5 -> 0.088102289 | ... L18: =L17/L5 -> 0.089231843
A20: Other income | C20: =Hist_Data!C7 -> 234 | D20: =Hist_Data!D7 -> 308 | E20: =Hist_Data!E7 -> 533 | F20: =Hist_Data!F7 -> 486 | G20: =Hist_Data!G7 -> 552 | H20: =Schedules!H83 -> 488.07 | I20: =Schedules!I83 -> 531.69394 | J20: =Schedules!J83 -> 594.47853 | K20: =Schedules!K83 -> 657.05383 | L20: =Schedules!L83 -> 722.3247
A21: Finance costs | C21: =Hist_Data!C13 -> 218 | D21: =Hist_Data!D13 -> 300 | E21: =Hist_Data!E13 -> 619 | F21: =Hist_Data!F13 -> 953 | G21: =Hist_Data!G13 -> 1180 | H21: =Schedules!H75 -> 1411.524 | I21: =Schedules!I75 -> 1527.7601 | J21: =Schedules!J75 -> 1593.2602 | K21: =Schedules!K75 -> 1614.9295 | L21: =Schedules!L75 -> 1606.8726
A22: Share of profit of associate / JV | C22: =Hist_Data!C18 -> 0 | D22: =Hist_Data!D18 -> 1 | E22: =Hist_Data!E18 -> 1 | F22: =Hist_Data!F18 -> 1 | G22: =Hist_Data!G18 -> 1 | H22: 0 | I22: 0 | J22: 0 | K22: 0 | L22: 0
A23: Exceptional items | C23: =Hist_Data!C20 -> 54 | D23: =Hist_Data!D20 -> 0 | E23: =Hist_Data!E20 -> 0 | F23: =Hist_Data!F20 -> 0 | G23: =Hist_Data!G20 -> 101 | H23: 0 | I23: 0 | J23: 0 | K23: 0 | L23: 0
A24: Profit before tax (PBT) | C24: =C17+C20-C21+C22-C23 -> 2904 | D24: =D17+D20-D21+D22-D23 -> 4447 | E24: =E17+E20-E21+E22-E23 -> 4623 | F24: =F17+F20-F21+F22-F23 -> 4535 | G24: =G17+G20-G21+G22-G23 -> 6801 | H24: =H17+H20-H21+H22-H23 -> 7862.5015 | I24: =I17+I20-I21+I22-I23 -> 9295.1878 | J24: =J17+J20-J21+J22-J23 -> 10833.548 | ... L24: =L17+L20-L21+L22-L23 -> 14014
A25: Income tax expense | C25: =Hist_Data!C24 -> 706 | D25: =Hist_Data!D24 -> 1173 | E25: =Hist_Data!E24 -> 1127 | F25: =Hist_Data!F24 -> 1198 | G25: =Hist_Data!G24 -> 1728 | H25: =MAX(0,H24)*Inputs!H80 -> 1997.0754 | I25: =MAX(0,I24)*Inputs!I80 -> 2360.9777 | J25: =MAX(0,J24)*Inputs!J80 -> 2751.7212 | K25: =MAX(0,K24)*Inputs!K80 -> 3143.9773 | L25: =MAX(0,L24)*Inputs!L80 -> 3559.5559
A26: effective tax rate | B26: % | C26: =C25/C24 -> 0.24311295 | D26: =D25/D24 -> 0.26377333 | E26: =E25/E24 -> 0.24378109 | F26: =F25/F24 -> 0.26416759 | G26: =G25/G24 -> 0.25408028 | H26: =H25/H24 -> 0.254 | I26: =I25/I24 -> 0.254 | J26: =J25/J24 -> 0.254 | ... L26: =L25/L24 -> 0.254
A27: Profit for the year (PAT) | C27: =C24-C25 -> 2198 | D27: =D24-D25 -> 3274 | E27: =E24-E25 -> 3496 | F27: =F24-F25 -> 3337 | G27: =G24-G25 -> 5073 | H27: =H24-H25 -> 5865.4261 | I27: =I24-I25 -> 6934.2101 | J27: =J24-J25 -> 8081.8267 | ... L27: =L24-L25 -> 10454.444
A28: PAT margin | B28: % | C28: =C27/C5 -> 0.076322095 | D28: =D27/D5 -> 0.08069008 | E28: =E27/E5 -> 0.068436301 | F28: =F27/F5 -> 0.055197168 | G28: =G27/G5 -> 0.057921538 | H28: =H27/H5 -> 0.056753518 | I28: =I27/I5 -> 0.058343486 | J28: =J27/J5 -> 0.060176437 | ... L28: =L27/L5 -> 0.06261478
A30: Diluted weighted shares (crore) | B30: cr | C30: =Inputs!$C$10 -> 88.78 | D30: =Inputs!$C$10 -> 88.78 | E30: =Inputs!$C$10 -> 88.78 | F30: =Inputs!$C$10 -> 88.78 | G30: =Inputs!$C$10 -> 88.78 | H30: =Inputs!$C$10 -> 88.78 | I30: =Inputs!$C$10 -> 88.78 | J30: =Inputs!$C$10 -> 88.78 | ... L30: =Inputs!$C$10 -> 88.78
A31: Basic & Diluted EPS (INR) | B31: INR | C31: =C27/C30 -> 24.757828 | D31: =D27/D30 -> 36.877675 | E31: =E27/E30 -> 39.378238 | F31: =F27/F30 -> 37.587294 | G31: =G27/G30 -> 57.141248 | H31: =H27/H30 -> 66.066976 | I31: =I27/I30 -> 78.105543 | J31: =J27/J30 -> 91.032065 | ... L31: =L27/L30 -> 117.75674

Sheet BS
A1: CONSOLIDATED BALANCE SHEET
A2: Grouped assets and liabilities; cash flows tie directly to cash balance, zero artificial plug
A4: Line Item (INR crore unless stated) | B4: Unit | C4: FY22A | D4: FY23A | E4: FY24A | F4: FY25A | G4: FY26A | H4: FY27E | I4: FY28E | J4: FY29E | K4: FY30E | L4: FY31E
A5: I. ASSETS
A6: PP&E, CWIP & Investment property | C6: =Hist_Data!C28+Hist_Data!C29+Hist_Data!C31 -> 1288 | D6: =Hist_Data!D28+Hist_Data!D29+Hist_Data!D31 -> 1477 | E6: =Hist_Data!E28+Hist_Data!E29+Hist_Data!E31 -> 1826 | F6: =Hist_Data!F28+Hist_Data!F29+Hist_Data!F31 -> 1948 | G6: =Hist_Data!G28+Hist_Data!G29+Hist_Data!G31 -> 2955 | H6: =Schedules!H39 -> 3536.361 | I6: =Schedules!I39 -> 4182.8284 | J6: =Schedules!J39 -> 4883.4581 | K6: =Schedules!K39 -> 5636.373 | L6: =Schedules!L39 -> 6437.5909
A7: Right-of-use assets (Ind AS 116) | C7: =Hist_Data!C30 -> 973 | D7: =Hist_Data!D30 -> 1285 | E7: =Hist_Data!E30 -> 1543 | F7: =Hist_Data!F30 -> 1774 | G7: =Hist_Data!G30 -> 2195 | H7: =Schedules!H45 -> 2701.6912 | I7: =Schedules!I45 -> 3241.8002 | J7: =Schedules!J45 -> 3806.79 | K7: =Schedules!K45 -> 4397.3448 | L7: =Schedules!L45 -> 5011.6268
A8: Goodwill | C8: =Hist_Data!C32 -> 123 | D8: =Hist_Data!D32 -> 123 | E8: =Hist_Data!E32 -> 123 | F8: =Hist_Data!F32 -> 123 | G8: =Hist_Data!G32 -> 758 | H8: =G8 -> 758 | I8: =H8 -> 758 | J8: =I8 -> 758 | K8: =J8 -> 758 | L8: =K8 -> 758
A9: Other intangible assets | C9: =Hist_Data!C33+Hist_Data!C34 -> 245 | D9: =Hist_Data!D33+Hist_Data!D34 -> 257 | E9: =Hist_Data!E33+Hist_Data!E34 -> 314 | F9: =Hist_Data!F33+Hist_Data!F34 -> 322 | G9: =Hist_Data!G33+Hist_Data!G34 -> 1133 | H9: =Schedules!H50 -> 1183.0684 | I9: =Schedules!I50 -> 1255.0329 | J9: =Schedules!J50 -> 1346.1729 | K9: =Schedules!K50 -> 1455.3853 | L9: =Schedules!L50 -> 1581.2751
A10: Non-current investments | C10: =Hist_Data!C35+Hist_Data!C36 -> 279 | D10: =Hist_Data!D35+Hist_Data!D36 -> 351 | E10: =Hist_Data!E35+Hist_Data!E36 -> 679 | F10: =Hist_Data!F35+Hist_Data!F36 -> 651 | G10: =Hist_Data!G35+Hist_Data!G36 -> 1257 | H10: =G10 -> 1257 | I10: =H10 -> 1257 | J10: =I10 -> 1257 | K10: =J10 -> 1257 | L10: =K10 -> 1257
A11: Other non-current assets | C11: =Hist_Data!C37+Hist_Data!C38+Hist_Data!C39+Hist_Data!C40+Hist_Data!C41 -> 832 | D11: =Hist_Data!D37+Hist_Data!D38+Hist_Data!D39+Hist_Data!D40+Hist_Data!D41 -> 1123 | E11: =Hist_Data!E37+Hist_Data!E38+Hist_Data!E39+Hist_Data!E40+Hist_Data!E41 -> 1457 | F11: =Hist_Data!F37+Hist_Data!F38+Hist_Data!F39+Hist_Data!F40+Hist_Data!F41 -> 1395 | G11: =Hist_Data!G37+Hist_Data!G38+Hist_Data!G39+Hist_Data!G40+Hist_Data!G41 -> 1482 | H11: =G11 -> 1482 | I11: =H11 -> 1482 | J11: =I11 -> 1482 | K11: =J11 -> 1482 | L11: =K11 -> 1482
A12: Total non-current assets | C12: =SUM(C6:C11) -> 3740 | D12: =SUM(D6:D11) -> 4616 | E12: =SUM(E6:E11) -> 5942 | F12: =SUM(F6:F11) -> 6213 | G12: =SUM(G6:G11) -> 9780 | H12: =SUM(H6:H11) -> 10918.121 | I12: =SUM(I6:I11) -> 12176.662 | J12: =SUM(J6:J11) -> 13533.421 | ... L12: =SUM(L6:L11) -> 16527.493
A13: Inventories | C13: =Hist_Data!C42 -> 13609 | D13: =Hist_Data!D42 -> 16584 | E13: =Hist_Data!E42 -> 19051 | F13: =Hist_Data!F42 -> 28184 | G13: =Hist_Data!G42 -> 42743 | H13: =Schedules!H11 -> 50020.974 | I13: =Schedules!I11 -> 57452.484 | J13: =Schedules!J11 -> 64840.357 | K13: =Schedules!K11 -> 72530.537 | L13: =Schedules!L11 -> 80508.896
A14: Trade receivables | C14: =Hist_Data!C44 -> 565 | D14: =Hist_Data!D44 -> 674 | E14: =Hist_Data!E44 -> 1018 | F14: =Hist_Data!F44 -> 1068 | G14: =Hist_Data!G44 -> 916 | H14: =Schedules!H12 -> 1132.5931 | I14: =Schedules!I12 -> 1302.4821 | J14: =Schedules!J12 -> 1471.8047 | K14: =Schedules!K12 -> 1648.4213 | L14: =Schedules!L12 -> 1829.7476
A15: Other current assets | C15: =Hist_Data!C47+Hist_Data!C48+Hist_Data!C49+Hist_Data!C50 -> 1692 | D15: =Hist_Data!D47+Hist_Data!D48+Hist_Data!D49+Hist_Data!D50 -> 1642 | E15: =Hist_Data!E47+Hist_Data!E48+Hist_Data!E49+Hist_Data!E50 -> 2347 | F15: =Hist_Data!F47+Hist_Data!F48+Hist_Data!F49+Hist_Data!F50 -> 2261 | G15: =Hist_Data!G47+Hist_Data!G48+Hist_Data!G49+Hist_Data!G50 -> 2956 | H15: =Schedules!H15 -> 3513.8701 | I15: =Schedules!I15 -> 4040.9506 | J15: =Schedules!J15 -> 4566.2742 | K15: =Schedules!K15 -> 5114.2271 | L15: =Schedules!L15 -> 5676.792
A16: Treasury investments & bank balances | C16: =Hist_Data!C43+Hist_Data!C46 -> 1369 | D16: =Hist_Data!D43+Hist_Data!D46 -> 3275 | E16: =Hist_Data!E43+Hist_Data!E46 -> 2783 | F16: =Hist_Data!F43+Hist_Data!F46 -> 2514 | G16: =Hist_Data!G43+Hist_Data!G46 -> 3293 | H16: =Schedules!H80 -> 3617.2192 | I16: =Schedules!I80 -> 4159.8021 | J16: =Schedules!J80 -> 4700.5764 | K16: =Schedules!K80 -> 5264.6455 | L16: =Schedules!L80 -> 5843.7565
A17: Cash & cash equivalents | C17: =Hist_Data!C45 -> 219 | D17: =Hist_Data!D45 -> 232 | E17: =Hist_Data!E45 -> 409 | F17: =Hist_Data!F45 -> 407 | G17: =Hist_Data!G45 -> 873 | H17: =CF!H34 -> 1033.4912 | I17: =CF!I34 -> 1188.5149 | J17: =CF!J34 -> 1343.0218 | K17: =CF!K34 -> 1504.1844 | L17: =CF!L34 -> 1669.6447
A18: Total current assets | C18: =SUM(C13:C17) -> 17454 | D18: =SUM(D13:D17) -> 22407 | E18: =SUM(E13:E17) -> 25608 | F18: =SUM(F13:F17) -> 34434 | G18: =SUM(G13:G17) -> 50781 | H18: =SUM(H13:H17) -> 59318.148 | I18: =SUM(I13:I17) -> 68144.233 | J18: =SUM(J13:J17) -> 76922.034 | ... L18: =SUM(L13:L17) -> 95528.837
A19: TOTAL ASSETS | C19: =C12+C18 -> 21194 | D19: =D12+D18 -> 27023 | E19: =E12+E18 -> 31550 | F19: =F12+F18 -> 40647 | G19: =G12+G18 -> 60561 | H19: =H12+H18 -> 70236.268 | I19: =I12+I18 -> 80320.895 | J19: =J12+J18 -> 90455.455 | ... L19: =L12+L18 -> 112056.33
A21: II. EQUITY & LIABILITIES
A22: Equity share capital | C22: =Hist_Data!C51 -> 89 | D22: =Hist_Data!D51 -> 89 | E22: =Hist_Data!E51 -> 89 | F22: =Hist_Data!F51 -> 89 | G22: =Hist_Data!G51 -> 89 | H22: =G22 -> 89 | I22: =H22 -> 89 | J22: =I22 -> 89 | K22: =J22 -> 89 | L22: =K22 -> 89
A23: Other equity (reserves & surplus) | C23: =Hist_Data!C52+Hist_Data!C53 -> 9244 | D23: =Hist_Data!D52+Hist_Data!D53 -> 11815 | E23: =Hist_Data!E52+Hist_Data!E53 -> 9304 | F23: =Hist_Data!F52+Hist_Data!F53 -> 11535 | G23: =Hist_Data!G52+Hist_Data!G53 -> 15614 | H23: =Schedules!H90 -> 20109.716 | I23: =Schedules!I90 -> 25460.261 | J23: =Schedules!J90 -> 31669.851 | K23: =Schedules!K90 -> 38721.644 | L23: =Schedules!L90 -> 46682.939
A24: Total equity | C24: =C22+C23 -> 9333 | D24: =D22+D23 -> 11904 | E24: =E22+E23 -> 9393 | F24: =F22+F23 -> 11624 | G24: =G22+G23 -> 15703 | H24: =H22+H23 -> 20198.716 | I24: =I22+I23 -> 25549.261 | J24: =J22+J23 -> 31758.851 | ... L24: =L22+L23 -> 46771.939
A25: Borrowings (term debt & credit facility) | C25: =Hist_Data!C54+Hist_Data!C60 -> 518 | D25: =Hist_Data!D54+Hist_Data!D60 -> 2195 | E25: =Hist_Data!E54+Hist_Data!E60 -> 7838 | F25: =Hist_Data!F54+Hist_Data!F60 -> 10286 | G25: =Hist_Data!G54+Hist_Data!G60 -> 11378 | H25: =Schedules!H63 -> 11691.93 | I25: =Schedules!I63 -> 10842.989 | J25: =Schedules!J63 -> 9145.4514 | K25: =Schedules!K63 -> 6791.3958 | L25: =Schedules!L63 -> 3715.391
A26: Gold on loan | C26: =Hist_Data!C61 -> 5398 | D26: =Hist_Data!D61 -> 5299 | E26: =Hist_Data!E61 -> 5341 | F26: =Hist_Data!F61 -> 7810 | G26: =Hist_Data!G61 -> 16070 | H26: =Schedules!H23 -> 18507.76 | I26: =Schedules!I23 -> 21257.419 | J26: =Schedules!J23 -> 23990.932 | K26: =Schedules!K23 -> 26836.299 | L26: =Schedules!L23 -> 29788.292
A27: Lease liabilities (non-current + current) | C27: =Hist_Data!C55+Hist_Data!C62 -> 1359 | D27: =Hist_Data!D55+Hist_Data!D62 -> 1873 | E27: =Hist_Data!E55+Hist_Data!E62 -> 2349 | F27: =Hist_Data!F55+Hist_Data!F62 -> 2681 | G27: =Hist_Data!G55+Hist_Data!G62 -> 3173 | H27: =Schedules!H70 -> 3476.7012 | I27: =Schedules!I70 -> 3865.5748 | J27: =Schedules!J70 -> 4319.5144 | K27: =Schedules!K70 -> 4830.2105 | L27: =Schedules!L70 -> 5388.9068
A28: Trade payables | C28: =Hist_Data!C63+Hist_Data!C64 -> 1294 | D28: =Hist_Data!D63+Hist_Data!D64 -> 1214 | E28: =Hist_Data!E63+Hist_Data!E64 -> 1410 | F28: =Hist_Data!F63+Hist_Data!F64 -> 1963 | G28: =Hist_Data!G63+Hist_Data!G64 -> 2864 | H28: =Schedules!H13 -> 3410.521 | I28: =Schedules!I13 -> 3917.2148 | J28: =Schedules!J13 -> 4420.9335 | K28: =Schedules!K13 -> 4945.2639 | L28: =Schedules!L13 -> 5489.2429
A29: Other financial liabilities | C29: =Hist_Data!C56+Hist_Data!C65 -> 444 | D29: =Hist_Data!D56+Hist_Data!D65 -> 572 | E29: =Hist_Data!E56+Hist_Data!E65 -> 678 | F29: =Hist_Data!F56+Hist_Data!F65 -> 1336 | G29: =Hist_Data!G56+Hist_Data!G65 -> 4406 | H29: =Schedules!H19 -> 4754.0595 | I29: =Schedules!I19 -> 5467.1684 | J29: =Schedules!J19 -> 6177.9003 | K29: =Schedules!K19 -> 6919.2484 | L29: =Schedules!L19 -> 7680.3657
A30: Other current liabilities | C30: =Hist_Data!C66 -> 2523 | D30: =Hist_Data!D66 -> 3517 | E30: =Hist_Data!E66 -> 4092 | F30: =Hist_Data!F66 -> 4441 | G30: =Hist_Data!G66 -> 6233 | H30: =Schedules!H17 -> 7337.7875 | I30: =Schedules!I17 -> 8438.4556 | J30: =Schedules!J17 -> 9535.4549 | K30: =Schedules!K17 -> 10679.709 | L30: =Schedules!L17 -> 11854.478
A31: Provisions (non-current & current) | C31: =Hist_Data!C57+Hist_Data!C67 -> 236 | D31: =Hist_Data!D57+Hist_Data!D67 -> 372 | E31: =Hist_Data!E57+Hist_Data!E67 -> 374 | F31: =Hist_Data!F57+Hist_Data!F67 -> 454 | G31: =Hist_Data!G57+Hist_Data!G67 -> 702 | H31: =Schedules!H21 -> 826.79296 | I31: =Schedules!I21 -> 950.8119 | J31: =Schedules!J21 -> 1074.4175 | K31: =Schedules!K21 -> 1203.3475 | L31: =Schedules!L21 -> 1335.7158
A32: Other liabilities (tax & deferred) | C32: =Hist_Data!C58+Hist_Data!C59+Hist_Data!C68+Hist_Data!C69 -> 89 | D32: =Hist_Data!D58+Hist_Data!D59+Hist_Data!D68+Hist_Data!D69 -> 77 | E32: =Hist_Data!E58+Hist_Data!E59+Hist_Data!E68+Hist_Data!E69 -> 75 | F32: =Hist_Data!F58+Hist_Data!F59+Hist_Data!F68+Hist_Data!F69 -> 52 | G32: =Hist_Data!G58+Hist_Data!G59+Hist_Data!G68+Hist_Data!G69 -> 32 | H32: =G32 -> 32 | I32: =H32 -> 32 | J32: =I32 -> 32 | K32: =J32 -> 32 | L32: =K32 -> 32
A33: Total liabilities | C33: =SUM(C25:C32) -> 11861 | D33: =SUM(D25:D32) -> 15119 | E33: =SUM(E25:E32) -> 22157 | F33: =SUM(F25:F32) -> 29023 | G33: =SUM(G25:G32) -> 44858 | H33: =SUM(H25:H32) -> 50037.552 | I33: =SUM(I25:I32) -> 54771.634 | J33: =SUM(J25:J32) -> 58696.604 | ... L33: =SUM(L25:L32) -> 65284.391
A34: TOTAL EQUITY & LIABILITIES | C34: =C24+C33 -> 21194 | D34: =D24+D33 -> 27023 | E34: =E24+E33 -> 31550 | F34: =F24+F33 -> 40647 | G34: =G24+G33 -> 60561 | H34: =H24+H33 -> 70236.268 | I34: =I24+I33 -> 80320.895 | J34: =J24+J33 -> 90455.455 | ... L34: =L24+L33 -> 112056.33
A36: Balance check: Assets - Liabilities & Equity (must be 0.00) | C36: =ROUND(C19-C34,2) -> 0 | D36: =ROUND(D19-D34,2) -> 0 | E36: =ROUND(E19-E34,2) -> 0 | F36: =ROUND(F19-F34,2) -> 0 | G36: =ROUND(G19-G34,2) -> 0 | H36: =ROUND(H19-H34,2) -> 0 | I36: =ROUND(I19-I34,2) -> 0 | J36: =ROUND(J19-J34,2) -> 0 | ... L36: =ROUND(L19-L34,2) -> 0

Sheet CF
A1: CONSOLIDATED CASH FLOW STATEMENT
A2: Ind AS indirect cash flow statement with explicit Ind AS 116 retail lease & gold-on-loan handling
A4: Line Item (INR crore unless stated) | B4: Unit | C4: FY22A | D4: FY23A | E4: FY24A | F4: FY25A | G4: FY26A | H4: FY27E | I4: FY28E | J4: FY29E | K4: FY30E | L4: FY31E
A5: Profit before tax (PBT) | C5: =IS!C24 -> 2904 | D5: =IS!D24 -> 4447 | E5: =IS!E24 -> 4623 | F5: =IS!F24 -> 4535 | G5: =IS!G24 -> 6801 | H5: =IS!H24 -> 7862.5015 | I5: =IS!I24 -> 9295.1878 | J5: =IS!J24 -> 10833.548 | ... L5: =IS!L24 -> 14014
A6: Add: Depreciation & amortisation | C6: =IS!C16 -> 399 | D6: =IS!D16 -> 441 | E6: =IS!E16 -> 584 | F6: =IS!F16 -> 693 | G6: =IS!G16 -> 826 | H6: =IS!H16 -> 1135.56 | I6: =IS!I16 -> 1356.1919 | J6: =IS!J16 -> 1597.8885 | ... L6: =IS!L16 -> 2131.8287
A7: Add: Finance costs | C7: =IS!C21 -> 218 | D7: =IS!D21 -> 300 | E7: =IS!E21 -> 619 | F7: =IS!F21 -> 953 | G7: =IS!G21 -> 1180 | H7: =IS!H21 -> 1411.524 | I7: =IS!I21 -> 1527.7601 | J7: =IS!J21 -> 1593.2602 | ... L7: =IS!L21 -> 1606.8726
A8: Other non-cash & non-operating adjustments | C8: =Hist_Data!C94-C5-C6-C7-C10-C11-C12-C13-C14-C15-C16 -> -222 | D8: =Hist_Data!D94-D5-D6-D7-D10-D11-D12-D13-D14-D15-D16 -> -251 | E8: =Hist_Data!E94-E5-E6-E7-E10-E11-E12-E13-E14-E15-E16 -> -422 | F8: =Hist_Data!F94-F5-F6-F7-F10-F11-F12-F13-F14-F15-F16 -> -407 | G8: =Hist_Data!G94-G5-G6-G7-G10-G11-G12-G13-G14-G15-G16 -> -360 | H8: =-IS!H20-IS!H22 -> -488.07 | I8: =-IS!I20-IS!I22 -> -531.69394 | J8: =-IS!J20-IS!J22 -> -594.47853 | K8: =-IS!K20-IS!K22 -> -657.05383 | L8: =-IS!L20-IS!L22 -> -722.3247
A9: Operating cash profit before working capital changes | C9: =SUM(C5:C8) -> 3299 | D9: =SUM(D5:D8) -> 4937 | E9: =SUM(E5:E8) -> 5404 | F9: =SUM(F5:F8) -> 5774 | G9: =SUM(G5:G8) -> 8447 | H9: =SUM(H5:H8) -> 9921.5155 | I9: =SUM(I5:I8) -> 11647.446 | J9: =SUM(J5:J8) -> 13430.218 | ... L9: =SUM(L5:L8) -> 17030.376
A10: (Increase) / decrease in trade receivables | C10: =Hist_Data!C83 -> -207 | D10: =Hist_Data!D83 -> -112 | E10: =Hist_Data!E83 -> -348 | F10: =Hist_Data!F83 -> -95 | G10: =Hist_Data!G83 -> 210 | H10: =-(BS!H14-BS!G14) -> -216.5931 | I10: =-(BS!I14-BS!H14) -> -169.88896 | J10: =-(BS!J14-BS!I14) -> -169.32267 | K10: =-(BS!K14-BS!J14) -> -176.61657 | L10: =-(BS!L14-BS!K14) -> -181.32634
A11: (Increase) / decrease in inventories | C11: =Hist_Data!C84 -> -5199 | D11: =Hist_Data!D84 -> -2977 | E11: =Hist_Data!E84 -> -2462 | F11: =Hist_Data!F84 -> -9072 | G11: =Hist_Data!G84 -> -11592 | H11: =-(BS!H13-BS!G13) -> -7277.9741 | I11: =-(BS!I13-BS!H13) -> -7431.5096 | J11: =-(BS!J13-BS!I13) -> -7387.8736 | K11: =-(BS!K13-BS!J13) -> -7690.1797 | L11: =-(BS!L13-BS!K13) -> -7978.3591
A12: (Increase) / decrease in other operating assets | C12: =Hist_Data!C85+Hist_Data!C86+Hist_Data!C87 -> -255 | D12: =Hist_Data!D85+Hist_Data!D86+Hist_Data!D87 -> -307 | E12: =Hist_Data!E85+Hist_Data!E86+Hist_Data!E87 -> -632 | F12: =Hist_Data!F85+Hist_Data!F86+Hist_Data!F87 -> -156 | G12: =Hist_Data!G85+Hist_Data!G86+Hist_Data!G87 -> -469 | H12: =-(BS!H15-BS!G15) -> -557.87008 | I12: =-(BS!I15-BS!H15) -> -527.08051 | J12: =-(BS!J15-BS!I15) -> -525.32358 | K12: =-(BS!K15-BS!J15) -> -547.9529 | L12: =-(BS!L15-BS!K15) -> -562.56498
A13: Increase / (decrease) in gold on loan | C13: =Hist_Data!C88 -> 1188 | D13: =Hist_Data!D88 -> -99 | E13: =Hist_Data!E88 -> 42 | F13: =Hist_Data!F88 -> 2468 | G13: =Hist_Data!G88 -> 7304 | H13: =BS!H26-BS!G26 -> 2437.7604 | I13: =BS!I26-BS!H26 -> 2749.6586 | J13: =BS!J26-BS!I26 -> 2733.5132 | K13: =BS!K26-BS!J26 -> 2845.3665 | L13: =BS!L26-BS!K26 -> 2951.9929
A14: Increase / (decrease) in trade payables | C14: =Hist_Data!C89 -> 504 | D14: =Hist_Data!D89 -> -89 | E14: =Hist_Data!E89 -> 196 | F14: =Hist_Data!F89 -> 564 | G14: =Hist_Data!G89 -> 472 | H14: =BS!H28-BS!G28 -> 546.52096 | I14: =BS!I28-BS!H28 -> 506.69384 | J14: =BS!J28-BS!I28 -> 503.71866 | K14: =BS!K28-BS!J28 -> 524.33043 | L14: =BS!L28-BS!K28 -> 543.97903
A15: Increase / (decrease) in other liabilities & provisions | C15: =Hist_Data!C90+Hist_Data!C91+Hist_Data!C92 -> 748 | D15: =Hist_Data!D90+Hist_Data!D91+Hist_Data!D92 -> 1171 | E15: =Hist_Data!E90+Hist_Data!E91+Hist_Data!E92 -> 668 | F15: =Hist_Data!F90+Hist_Data!F91+Hist_Data!F92 -> 1065 | G15: =Hist_Data!G90+Hist_Data!G91+Hist_Data!G92 -> 2955 | H15: =(BS!H29-BS!G29)+(BS!H30-BS!G30)+(BS!H31-BS!G31)+(BS!H32-BS!G32) -> 1577.64 | I15: =(BS!I29-BS!H29)+(BS!I30-BS!H30)+(BS!I31-BS!H31)+(BS!I32-BS!H32) -> 1937.796 | J15: =(BS!J29-BS!I29)+(BS!J30-BS!I30)+(BS!J31-BS!I31)+(BS!J32-BS!I32) -> 1931.3367 | K15: =(BS!K29-BS!J29)+(BS!K30-BS!J30)+(BS!K31-BS!J31)+(BS!K32-BS!J32) -> 2014.5327 | L15: =(BS!L29-BS!K29)+(BS!L30-BS!K30)+(BS!L31-BS!K31)+(BS!L32-BS!K32) -> 2068.2536
A16: Direct taxes paid | C16: =Hist_Data!C93 -> -802 | D16: =Hist_Data!D93 -> -1154 | E16: =Hist_Data!E93 -> -1173 | F16: =Hist_Data!F93 -> -1089 | G16: =Hist_Data!G93 -> -1737 | H16: =-IS!H25 -> -1997.0754 | I16: =-IS!I25 -> -2360.9777 | J16: =-IS!J25 -> -2751.7212 | K16: =-IS!K25 -> -3143.9773 | L16: =-IS!L25 -> -3559.5559
A17: Cash flow from operations (CFO) | C17: =SUM(C9:C16) -> -724 | D17: =SUM(D9:D16) -> 1370 | E17: =SUM(E9:E16) -> 1695 | F17: =SUM(F9:F16) -> -541 | G17: =SUM(G9:G16) -> 5590 | H17: =SUM(H9:H16) -> 4433.9242 | I17: =SUM(I9:I16) -> 6352.1374 | J17: =SUM(J9:J16) -> 7764.5457 | ... L17: =SUM(L9:L16) -> 10312.795
A19: Capital expenditure (PP&E, CWIP, Intangibles) | C19: =Hist_Data!C95 -> -224 | D19: =Hist_Data!D95 -> -432 | E19: =Hist_Data!E95 -> -691 | F19: =Hist_Data!F95 -> -494 | G19: =Hist_Data!G95 -> -902 | H19: =-Schedules!H32 -> -1240.1894 | I19: =-Schedules!I32 -> -1426.2179 | J19: =-Schedules!J32 -> -1611.6262 | K19: =-Schedules!K32 -> -1805.0213 | L19: =-Schedules!L32 -> -2003.5737
A20: Other investing cash flows (treasury, yield, acquisitions) | C20: =Hist_Data!C96-C19 -> 1388 | D20: =Hist_Data!D96-D19 -> -1379 | E20: =Hist_Data!E96-E19 -> 502 | F20: =Hist_Data!F96-F19 -> 1040 | G20: =Hist_Data!G96-G19 -> -2032 | H20: =-(BS!H16-BS!G16)-(BS!H10-BS!G10)-(BS!H11-BS!G11)-(BS!H8-BS!G8)+IS!H20+IS!H22 -> 163.8508 | I20: =-(BS!I16-BS!H16)-(BS!I10-BS!H10)-(BS!I11-BS!H11)-(BS!I8-BS!H8)+IS!I20+IS!I22 -> -10.888944 | J20: =-(BS!J16-BS!I16)-(BS!J10-BS!I10)-(BS!J11-BS!I11)-(BS!J8-BS!I8)+IS!J20+IS!J22 -> 53.704256 | K20: =-(BS!K16-BS!J16)-(BS!K10-BS!J10)-(BS!K11-BS!J11)-(BS!K8-BS!J8)+IS!K20+IS!K22 -> 92.984673 | L20: =-(BS!L16-BS!K16)-(BS!L10-BS!K10)-(BS!L11-BS!K11)-(BS!L8-BS!K8)+IS!L20+IS!L22 -> 143.21369
A21: Cash flow from investing (CFI) | C21: =C19+C20 -> 1164 | D21: =D19+D20 -> -1811 | E21: =E19+E20 -> -189 | F21: =F19+F20 -> 546 | G21: =G19+G20 -> -2934 | H21: =H19+H20 -> -1076.3386 | I21: =I19+I20 -> -1437.1068 | J21: =J19+J20 -> -1557.9219 | ... L21: =L19+L20 -> -1860.36
A23: Long-term borrowings proceeds / (repayment) | C23: =Hist_Data!C101+Hist_Data!C102 -> -7 | D23: =Hist_Data!D101+Hist_Data!D102 -> -7 | E23: =Hist_Data!E101+Hist_Data!E102 -> 3301 | F23: =Hist_Data!F101+Hist_Data!F102 -> -308 | G23: =Hist_Data!G101+Hist_Data!G102 -> -2632 | H23: =-Schedules!H55 -> -93 | I23: =-Schedules!I55 -> 0 | J23: =-Schedules!J55 -> 0 | K23: =-Schedules!K55 -> 0 | L23: =-Schedules!L55 -> 0
A24: Short-term debt & revolver drawdown / (repayment) | C24: =Hist_Data!C103 -> 349 | D24: =Hist_Data!D103 -> 1684 | E24: =Hist_Data!E103 -> 2328 | F24: =Hist_Data!F103 -> 2529 | G24: =Hist_Data!G103 -> 3314 | H24: =Schedules!H61 -> 406.92959 | I24: =Schedules!I61 -> -848.94054 | J24: =Schedules!J61 -> -1697.5377 | K24: =Schedules!K61 -> -2354.0556 | L24: =Schedules!L61 -> -3076.0048
A25: Dividends paid | C25: =Hist_Data!C104 -> -355 | D25: =Hist_Data!D104 -> -666 | E25: =Hist_Data!E104 -> -888 | F25: =Hist_Data!F104 -> -976 | G25: =Hist_Data!G104 -> -976 | H25: =-Schedules!H89 -> -1369.71 | I25: =-Schedules!I89 -> -1583.6651 | J25: =-Schedules!J89 -> -1872.2367 | K25: =-Schedules!K89 -> -2182.0932 | L25: =-Schedules!L89 -> -2493.1493
A26: Lease liabilities principal & interest repayment | C26: =Hist_Data!C105 -> -172 | D26: =Hist_Data!D105 -> -254 | E26: =Hist_Data!E105 -> -318 | F26: =Hist_Data!F105 -> -700 | G26: =Hist_Data!G105 -> -865 | H26: =-Schedules!H69 -> -1015.36 | I26: =-Schedules!I69 -> -1112.5444 | J26: =-Schedules!J69 -> -1236.9839 | K26: =-Schedules!K69 -> -1382.2446 | L26: =-Schedules!L69 -> -1545.6674
A27: Finance costs paid (borrowings & gold on loan) | C27: =Hist_Data!C106 -> -218 | D27: =Hist_Data!D106 -> -300 | E27: =Hist_Data!E106 -> -619 | F27: =Hist_Data!F106 -> -538 | G27: =Hist_Data!G106 -> -1000 | H27: =-Schedules!H76 -> -1125.954 | I27: =-Schedules!I76 -> -1214.857 | J27: =-Schedules!J76 -> -1245.3585 | K27: =-Schedules!K76 -> -1226.1732 | L27: =-Schedules!L76 -> -1172.1536
A28: Other financing transactions | C28: =Hist_Data!C97-SUM(C23:C27) -> 0 | D28: =Hist_Data!D97-SUM(D23:D27) -> 0 | E28: =Hist_Data!E97-SUM(E23:E27) -> -5133 | F28: =Hist_Data!F97-SUM(F23:F27) -> -14 | G28: =Hist_Data!G97-SUM(G23:G27) -> 0 | H28: 0 | I28: 0 | J28: 0 | K28: 0 | L28: 0
A29: Cash flow from financing (CFF) | C29: =SUM(C23:C28) -> -403 | D29: =SUM(D23:D28) -> 457 | E29: =SUM(E23:E28) -> -1329 | F29: =SUM(F23:F28) -> -7 | G29: =SUM(G23:G28) -> -2159 | H29: =SUM(H23:H28) -> -3197.0944 | I29: =SUM(I23:I28) -> -4760.0069 | J29: =SUM(J23:J28) -> -6052.1168 | ... L29: =SUM(L23:L28) -> -8286.9751
A31: Net change in cash & equivalents | C31: =C17+C21+C29 -> 37 | D31: =D17+D21+D29 -> 16 | E31: =E17+E21+E29 -> 177 | F31: =F17+F21+F29 -> -2 | G31: =G17+G21+G29 -> 497 | H31: =H17+H21+H29 -> 160.4912 | I31: =I17+I21+I29 -> 155.02368 | J31: =J17+J21+J29 -> 154.50693 | ... L31: =L17+L21+L29 -> 165.46029
A32: Opening cash balance | C32: =Hist_Data!C99 -> 181 | D32: =Hist_Data!D99 -> 219 | E32: =Hist_Data!E99 -> 232 | F32: =Hist_Data!F99 -> 409 | G32: =Hist_Data!G99 -> 407 | H32: =G34 -> 873 | I32: =H34 -> 1033.4912 | J32: =I34 -> 1188.5149 | K32: =J34 -> 1343.0218 | L32: =K34 -> 1504.1844
A33: Foreign exchange / other adjustments | C33: =Hist_Data!C100-C32-C31 -> 1 | D33: =Hist_Data!D100-D32-D31 -> -3 | E33: =Hist_Data!E100-E32-E31 -> 0 | F33: =Hist_Data!F100-F32-F31 -> 0 | G33: =Hist_Data!G100-G32-G31 -> -31 | H33: 0 | I33: 0 | J33: 0 | K33: 0 | L33: 0
A34: Closing cash balance | C34: =C32+C31+C33 -> 219 | D34: =D32+D31+D33 -> 232 | E34: =E32+E31+E33 -> 409 | F34: =F32+F31+F33 -> 407 | G34: =G32+G31+G33 -> 873 | H34: =H32+H31+H33 -> 1033.4912 | I34: =I32+I31+I33 -> 1188.5149 | J34: =J32+J31+J33 -> 1343.0218 | ... L34: =L32+L31+L33 -> 1669.6447
A35: Check: Closing cash vs Balance Sheet cash (must be 0.00) | C35: =ROUND(C34-BS!C17,2) -> 0 | D35: =ROUND(D34-BS!D17,2) -> 0 | E35: =ROUND(E34-BS!E17,2) -> 0 | F35: =ROUND(F34-BS!F17,2) -> 0 | G35: =ROUND(G34-BS!G17,2) -> 0 | H35: =ROUND(H34-BS!H17,2) -> 0 | I35: =ROUND(I34-BS!I17,2) -> 0 | J35: =ROUND(J34-BS!J17,2) -> 0 | ... L35: =ROUND(L34-BS!L17,2) -> 0
A37: Free cash flow to firm (CFO + Capex) | C37: =C17+C19 -> -948 | D37: =D17+D19 -> 938 | E37: =E17+E19 -> 1004 | F37: =F17+F19 -> -1035 | G37: =G17+G19 -> 4688 | H37: =H17+H19 -> 3193.7348 | I37: =I17+I19 -> 4925.9196 | J37: =J17+J19 -> 6152.9195 | ... L37: =L17+L19 -> 8309.2217
A38: Free cash flow excluding Gold on Loan movement | C38: =C37-C13 -> -2136 | D38: =D37-D13 -> 1037 | E38: =E37-E13 -> 962 | F38: =F37-F13 -> -3503 | G38: =G37-G13 -> -2616 | H38: =H37-H13 -> 755.9744 | I38: =I37-I13 -> 2176.261 | J38: =J37-J13 -> 3419.4063 | ... L38: =L37-L13 -> 5357.2288

Sheet Schedules
A1: SUPPORTING OPERATIONAL SCHEDULES
A2: Working capital, fixed assets, debt revolver, leases, treasury, equity & operational ratios
A4: Line Item (INR crore unless stated) | B4: Unit | C4: FY22A | D4: FY23A | E4: FY24A | F4: FY25A | G4: FY26A | H4: FY27E | I4: FY28E | J4: FY29E | K4: FY30E | L4: FY31E
A5: A. WORKING CAPITAL & GOLD-ON-LOAN SCHEDULE
A6: Revenue from operations | C6: =IS!C5 -> 28799 | D6: =IS!D5 -> 40575 | E6: =IS!E5 -> 51084 | F6: =IS!F5 -> 60456 | G6: =IS!G5 -> 87584 | H6: =IS!H5 -> 103349.12 | I6: =IS!I5 -> 118851.49 | J6: =IS!J5 -> 134302.18 | ... L6: =IS!L5 -> 166964.47
A7: Cost of goods sold | C7: =IS!C7 -> 21641 | D7: =IS!D7 -> 30355 | E7: =IS!E7 -> 39432 | F7: =IS!F7 -> 47456 | G7: =IS!G7 -> 70307 | H7: =IS!H7 -> 82989.343 | I7: =IS!I7 -> 95318.893 | J7: =IS!J7 -> 107576.05 | ... L7: =IS!L7 -> 133571.58
A8: Inventory days (on COGS) | B8: days | C8: =C11/C7*365 -> 229.53121 | D8: =D11/D7*365 -> 199.41229 | E8: =E11/E7*365 -> 176.34447 | F8: =F11/F7*365 -> 216.77259 | G8: =G11/G7*365 -> 221.90102 | H8: =Inputs!H51 -> 220 | I8: =Inputs!I51 -> 220 | J8: =Inputs!J51 -> 220 | K8: =Inputs!K51 -> 220 | L8: =Inputs!L51 -> 220
A9: Receivable days (on Revenue) | B9: days | C9: =C12/C6*365 -> 7.1608389 | D9: =D12/D6*365 -> 6.063093 | E9: =E12/E6*365 -> 7.2737061 | F9: =F12/F6*365 -> 6.4479952 | G9: =G12/G6*365 -> 3.8173639 | H9: =Inputs!H73 -> 4 | I9: =Inputs!I73 -> 4 | J9: =Inputs!J73 -> 4 | K9: =Inputs!K73 -> 4 | L9: =Inputs!L73 -> 4
A10: Payable days (on COGS) | B10: days | C10: =C13/C7*365 -> 21.824777 | D10: =D13/D7*365 -> 14.597595 | E10: =E13/E7*365 -> 13.051582 | F10: =F13/F7*365 -> 15.098091 | G10: =G13/G7*365 -> 14.868505 | H10: =Inputs!H56 -> 15 | I10: =Inputs!I56 -> 15 | J10: =Inputs!J56 -> 15 | K10: =Inputs!K56 -> 15 | L10: =Inputs!L56 -> 15
A11: Inventories | C11: =BS!C13 -> 13609 | D11: =BS!D13 -> 16584 | E11: =BS!E13 -> 19051 | F11: =BS!F13 -> 28184 | G11: =BS!G13 -> 42743 | H11: =H7*H8/365 -> 50020.974 | I11: =I7*I8/365 -> 57452.484 | J11: =J7*J8/365 -> 64840.357 | K11: =K7*K8/365 -> 72530.537 | L11: =L7*L8/365 -> 80508.896
A12: Trade receivables | C12: =BS!C14 -> 565 | D12: =BS!D14 -> 674 | E12: =BS!E14 -> 1018 | F12: =BS!F14 -> 1068 | G12: =BS!G14 -> 916 | H12: =H6*H9/365 -> 1132.5931 | I12: =I6*I9/365 -> 1302.4821 | J12: =J6*J9/365 -> 1471.8047 | K12: =K6*K9/365 -> 1648.4213 | L12: =L6*L9/365 -> 1829.7476
A13: Trade payables | C13: =BS!C28 -> 1294 | D13: =BS!D28 -> 1214 | E13: =BS!E28 -> 1410 | F13: =BS!F28 -> 1963 | G13: =BS!G28 -> 2864 | H13: =H7*H10/365 -> 3410.521 | I13: =I7*I10/365 -> 3917.2148 | J13: =J7*J10/365 -> 4420.9335 | K13: =K7*K10/365 -> 4945.2639 | L13: =L7*L10/365 -> 5489.2429
A14: Other current assets % revenue | B14: % | C14: =BS!C15/C6 -> 0.05875204 | D14: =BS!D15/D6 -> 0.040468269 | E14: =BS!E15/E6 -> 0.045943935 | F14: =BS!F15/F6 -> 0.0373991 | G14: =BS!G15/G6 -> 0.033750457 | H14: =Inputs!H74 -> 0.034 | I14: =Inputs!I74 -> 0.034 | J14: =Inputs!J74 -> 0.034 | K14: =Inputs!K74 -> 0.034 | L14: =Inputs!L74 -> 0.034
A15: Other current assets | C15: =BS!C15 -> 1692 | D15: =BS!D15 -> 1642 | E15: =BS!E15 -> 2347 | F15: =BS!F15 -> 2261 | G15: =BS!G15 -> 2956 | H15: =H6*H14 -> 3513.8701 | I15: =I6*I14 -> 4040.9506 | J15: =J6*J14 -> 4566.2742 | K15: =K6*K14 -> 5114.2271 | L15: =L6*L14 -> 5676.792
A16: Other current liabilities % revenue | B16: % | C16: =BS!C30/C6 -> 0.087607209 | D16: =BS!D30/D6 -> 0.08667899 | E16: =BS!E30/E6 -> 0.080103359 | F16: =BS!F30/F6 -> 0.073458383 | G16: =BS!G30/G6 -> 0.071165966 | H16: =Inputs!H75 -> 0.071 | I16: =Inputs!I75 -> 0.071 | J16: =Inputs!J75 -> 0.071 | K16: =Inputs!K75 -> 0.071 | L16: =Inputs!L75 -> 0.071
A17: Other current liabilities | C17: =BS!C30 -> 2523 | D17: =BS!D30 -> 3517 | E17: =BS!E30 -> 4092 | F17: =BS!F30 -> 4441 | G17: =BS!G30 -> 6233 | H17: =H6*H16 -> 7337.7875 | I17: =I6*I16 -> 8438.4556 | J17: =J6*J16 -> 9535.4549 | K17: =K6*K16 -> 10679.709 | L17: =L6*L16 -> 11854.478
A18: Other financial liabilities % revenue | B18: % | C18: =BS!C29/C6 -> 0.015417202 | D18: =BS!D29/D6 -> 0.014097351 | E18: =BS!E29/E6 -> 0.013272257 | F18: =BS!F29/F6 -> 0.022098716 | G18: =BS!G29/G6 -> 0.050305992 | H18: =Inputs!H76 -> 0.046 | I18: =Inputs!I76 -> 0.046 | J18: =Inputs!J76 -> 0.046 | K18: =Inputs!K76 -> 0.046 | L18: =Inputs!L76 -> 0.046
A19: Other financial liabilities | C19: =BS!C29 -> 444 | D19: =BS!D29 -> 572 | E19: =BS!E29 -> 678 | F19: =BS!F29 -> 1336 | G19: =BS!G29 -> 4406 | H19: =H6*H18 -> 4754.0595 | I19: =I6*I18 -> 5467.1684 | J19: =J6*J18 -> 6177.9003 | K19: =K6*K18 -> 6919.2484 | L19: =L6*L18 -> 7680.3657
A20: Provisions % revenue | B20: % | C20: =BS!C31/C6 -> 0.008194729 | D20: =BS!D31/D6 -> 0.009168207 | E20: =BS!E31/E6 -> 0.0073212748 | F20: =BS!F31/F6 -> 0.0075095938 | G20: =BS!G31/G6 -> 0.0080151626 | H20: =Inputs!H77 -> 0.008 | I20: =Inputs!I77 -> 0.008 | J20: =Inputs!J77 -> 0.008 | K20: =Inputs!K77 -> 0.008 | L20: =Inputs!L77 -> 0.008
A21: Provisions | C21: =BS!C31 -> 236 | D21: =BS!D31 -> 372 | E21: =BS!E31 -> 374 | F21: =BS!F31 -> 454 | G21: =BS!G31 -> 702 | H21: =H6*H20 -> 826.79296 | I21: =I6*I20 -> 950.8119 | J21: =J6*J20 -> 1074.4175 | K21: =K6*K20 -> 1203.3475 | L21: =L6*L20 -> 1335.7158
A22: Gold on loan % of inventories | B22: % | C22: =BS!C26/C11 -> 0.39664928 | D22: =BS!D26/D11 -> 0.31952484 | E22: =BS!E26/E11 -> 0.28035274 | F22: =BS!F26/F11 -> 0.27710758 | G22: =BS!G26/G11 -> 0.37596799 | H22: =Inputs!H61 -> 0.37 | I22: =Inputs!I61 -> 0.37 | J22: =Inputs!J61 -> 0.37 | K22: =Inputs!K61 -> 0.37 | L22: =Inputs!L61 -> 0.37
A23: Gold on loan | C23: =BS!C26 -> 5398 | D23: =BS!D26 -> 5299 | E23: =BS!E26 -> 5341 | F23: =BS!F26 -> 7810 | G23: =BS!G26 -> 16070 | H23: =H11*H22 -> 18507.76 | I23: =I11*I22 -> 21257.419 | J23: =J11*J22 -> 23990.932 | K23: =K11*K22 -> 26836.299 | L23: =L11*L22 -> 29788.292
A24: Operating NWC (excluding Gold on Loan) | C24: =C11+C12+C15-C13-C17-C19-C21 -> 11369 | D24: =D11+D12+D15-D13-D17-D19-D21 -> 13225 | E24: =E11+E12+E15-E13-E17-E19-E21 -> 15862 | F24: =F11+F12+F15-F13-F17-F19-F21 -> 23319 | G24: =G11+G12+G15-G13-G17-G19-G21 -> 32410 | H24: =H11+H12+H15-H13-H17-H19-H21 -> 38338.276 | I24: =I11+I12+I15-I13-I17-I19-I21 -> 44022.266 | J24: =J11+J12+J15-J13-J17-J19-J21 -> 49669.73 | ... L24: =L11+L12+L15-L13-L17-L19-L21 -> 61655.634
A25: Operating NWC (net of Gold on Loan) | C25: =C24-C23 -> 5971 | D25: =D24-D23 -> 7926 | E25: =E24-E23 -> 10521 | F25: =F24-F23 -> 15509 | G25: =G24-G23 -> 16340 | H25: =H24-H23 -> 19830.516 | I25: =I24-I23 -> 22764.847 | J25: =J24-J23 -> 25678.798 | ... L25: =L24-L23 -> 31867.342
A26: Change in NWC (excluding GoL) | D26: =D24-C24 -> 1856 | E26: =E24-D24 -> 2637 | F26: =F24-E24 -> 7457 | G26: =G24-F24 -> 9091 | H26: =H24-G24 -> 5928.2763 | I26: =I24-H24 -> 5683.9892 | J26: =J24-I24 -> 5647.4645 | K26: =K24-J24 -> 5875.886 | L26: =L24-K24 -> 6110.0178
A27: Change in NWC (net of GoL) | D27: =D25-C25 -> 1955 | E27: =E25-D25 -> 2595 | F27: =F25-E25 -> 4988 | G27: =G25-F25 -> 831 | H27: =H25-G25 -> 3490.5159 | I27: =I25-H25 -> 2934.3307 | J27: =J25-I25 -> 2913.9513 | K27: =K25-J25 -> 3030.5195 | L27: =L25-K25 -> 3158.0249
A29: B. TANGIBLE, INTANGIBLE & IND AS 116 ROU LEASE SCHEDULE
A30: Capex % revenue | B30: % | C30: =C32/C6 -> 0.0077780478 | D30: =D32/D6 -> 0.01064695 | E30: =E32/E6 -> 0.01352674 | F30: =F32/F6 -> 0.008171232 | G30: =G32/G6 -> 0.010298685 | H30: =Inputs!H46 -> 0.012 | I30: =Inputs!I46 -> 0.012 | J30: =Inputs!J46 -> 0.012 | K30: =Inputs!K46 -> 0.012 | L30: =Inputs!L46 -> 0.012
A31: intangible share of capex | B31: % | H31: =Inputs!H85 -> 0.15 | I31: =Inputs!I85 -> 0.15 | J31: =Inputs!J85 -> 0.15 | K31: =Inputs!K85 -> 0.15 | L31: =Inputs!L85 -> 0.15
A32: Total capex (PP&E + Intangibles) | C32: =-CF!C19 -> 224 | D32: =-CF!D19 -> 432 | E32: =-CF!E19 -> 691 | F32: =-CF!F19 -> 494 | G32: =-CF!G19 -> 902 | H32: =H6*H30 -> 1240.1894 | I32: =I6*I30 -> 1426.2179 | J32: =J6*J30 -> 1611.6262 | K32: =K6*K30 -> 1805.0213 | L32: =L6*L30 -> 2003.5737
A33: capex - intangibles | H33: =H32*H31 -> 186.02842 | I33: =I32*I31 -> 213.93268 | J33: =J32*J31 -> 241.74393 | K33: =K32*K31 -> 270.7532 | L33: =L32*L31 -> 300.53605
A34: capex - tangible PP&E | H34: =H32-H33 -> 1054.161 | I34: =I32-I33 -> 1212.2852 | J34: =J32-J33 -> 1369.8823 | K34: =K32-K33 -> 1534.2681 | L34: =L32-L33 -> 1703.0376
A35: PP&E depreciation % opening balance | B35: % | F35: =Hist_Data!F113/BS!E6 -> 0.14895947 | G35: =Hist_Data!G113/BS!F6 -> 0.16940452 | H35: =Inputs!H82 -> 0.16 | I35: =Inputs!I82 -> 0.16 | J35: =Inputs!J82 -> 0.16 | K35: =Inputs!K82 -> 0.16 | L35: =Inputs!L82 -> 0.16
A36: PP&E: Opening balance | H36: =G39 -> 2955 | I36: =H39 -> 3536.361 | J36: =I39 -> 4182.8284 | K36: =J39 -> 4883.4581 | L36: =K39 -> 5636.373
A37: + PP&E additions | H37: =H34 -> 1054.161 | I37: =I34 -> 1212.2852 | J37: =J34 -> 1369.8823 | K37: =K34 -> 1534.2681 | L37: =L34 -> 1703.0376
A38: - depreciation expense | F38: =Hist_Data!F113 -> 272 | G38: =Hist_Data!G113 -> 330 | H38: =H36*H35 -> 472.8 | I38: =I36*I35 -> 565.81776 | J38: =J36*J35 -> 669.25255 | K38: =K36*K35 -> 781.3533 | L38: =L36*L35 -> 901.81967
A39: PP&E: Closing balance | C39: =BS!C6 -> 1288 | D39: =BS!D6 -> 1477 | E39: =BS!E6 -> 1826 | F39: =BS!F6 -> 1948 | G39: =BS!G6 -> 2955 | H39: =H36+H37-H38 -> 3536.361 | I39: =I36+I37-I38 -> 4182.8284 | J39: =J36+J37-J38 -> 4883.4581 | K39: =K36+K37-K38 -> 5636.373 | L39: =L36+L37-L38 -> 6437.5909
A40: ROU new lease additions % revenue | B40: % | F40: =(F70-E70+F69-F68)/F6 -> 0.013398174 | G40: =(G70-F70+G69-G68)/G6 -> 0.012673548 | H40: =Inputs!H86 -> 0.01 | I40: =Inputs!I86 -> 0.01 | J40: =Inputs!J86 -> 0.01 | K40: =Inputs!K86 -> 0.01 | L40: =Inputs!L86 -> 0.01
A41: ROU depreciation % opening balance | B41: % | F41: =Hist_Data!F114/BS!E7 -> 0.23331173 | G41: =Hist_Data!G114/BS!F7 -> 0.24069899 | H41: =Inputs!H83 -> 0.24 | I41: =Inputs!I83 -> 0.24 | J41: =Inputs!J83 -> 0.24 | K41: =Inputs!K83 -> 0.24 | L41: =Inputs!L83 -> 0.24
A42: ROU Assets: Opening balance | H42: =G45 -> 2195 | I42: =H45 -> 2701.6912 | J42: =I45 -> 3241.8002 | K42: =J45 -> 3806.79 | L42: =K45 -> 4397.3448
...

Sheet Earnings_Quality
A1: EARNINGS QUALITY & DUPONT ANALYSIS
A2: Forensic accounting audit: Sloan accruals, DuPont 3-stage, cash conversion cycle & Altman Z
A4: Line Item (INR crore unless stated) | B4: Unit | C4: FY22A | D4: FY23A | E4: FY24A | F4: FY25A | G4: FY26A | H4: FY27E | I4: FY28E | J4: FY29E | K4: FY30E | L4: FY31E
A5: 1. ACCRUAL METRICS & EARNINGS QUALITY AUDIT
A6: Reported Profit After Tax (PAT) | C6: =IS!C27 -> 2198 | D6: =IS!D27 -> 3274 | E6: =IS!E27 -> 3496 | F6: =IS!F27 -> 3337 | G6: =IS!G27 -> 5073 | H6: =IS!H27 -> 5865.4261 | I6: =IS!I27 -> 6934.2101 | J6: =IS!J27 -> 8081.8267 | ... L6: =IS!L27 -> 10454.444
A7: Cash Flow from Operations (CFO) | C7: =CF!C17 -> -724 | D7: =CF!D17 -> 1370 | E7: =CF!E17 -> 1695 | F7: =CF!F17 -> -541 | G7: =CF!G17 -> 5590 | H7: =CF!H17 -> 4433.9242 | I7: =CF!I17 -> 6352.1374 | J7: =CF!J17 -> 7764.5457 | ... L7: =CF!L17 -> 10312.795
A8: Total Accounting Accruals (PAT - CFO) | C8: =C6-C7 -> 2922 | D8: =D6-D7 -> 1904 | E8: =E6-E7 -> 1801 | F8: =F6-F7 -> 3878 | G8: =G6-G7 -> -517 | H8: =H6-H7 -> 1431.5019 | I8: =I6-I7 -> 582.07269 | J8: =J6-J7 -> 317.28103 | ... L8: =L6-L7 -> 141.64838
A9: Sloan Accrual Ratio ((PAT - CFO) / Avg Total Assets) | B9: % | D9: =D8/AVERAGE(BS!C19,BS!D19) -> 0.078976295 | E9: =E8/AVERAGE(BS!D19,BS!E19) -> 0.061495911 | F9: =F8/AVERAGE(BS!E19,BS!F19) -> 0.10742829 | G9: =G8/AVERAGE(BS!F19,BS!G19) -> -0.010216584 | H9: =H8/AVERAGE(BS!G19,BS!H19) -> 0.021888865 | I9: =I8/AVERAGE(BS!H19,BS!I19) -> 0.0077322483 | J9: =J8/AVERAGE(BS!I19,BS!J19) -> 0.003715749 | K9: =K8/AVERAGE(BS!J19,BS!K19) -> 0.002257088 | L9: =L8/AVERAGE(BS!K19,BS!L19) -> 0.0013293798
A10: Cash Generation Ratio (CFO / PAT > 1.0x indicates healthy quality) | B10: x | C10: =C7/C6 -> -0.32939035 | D10: =D7/D6 -> 0.41844838 | E10: =E7/E6 -> 0.48483982 | F10: =F7/F6 -> -0.16212167 | G10: =G7/G6 -> 1.1019121 | H10: =H7/H6 -> 0.75594239 | I10: =I7/I6 -> 0.91605782 | J10: =J7/J6 -> 0.96074142 | ... L10: =L7/L6 -> 0.98645089
A11: Operating Cash Conversion (CFO / EBITDA) | B11: % | C11: =C7/IS!C14 -> -0.21670159 | D11: =D7/IS!D14 -> 0.28079524 | E11: =E7/IS!E14 -> 0.32029478 | F11: =F7/IS!F14 -> -0.095012294 | G11: =G7/IS!G14 -> 0.66906044 | H11: =H7/IS!H14 -> 0.4468999 | I11: =I7/IS!I14 -> 0.54536742 | J11: =J7/IS!J14 -> 0.57813995 | ... L11: =L7/IS!L14 -> 0.605553
A13: 2. WORKING CAPITAL EFFICIENCY & CASH CONVERSION CYCLE
A14: Days Inventory Outstanding (DIO) | B14: days | C14: =Schedules!C8 -> 229.53121 | D14: =Schedules!D8 -> 199.41229 | E14: =Schedules!E8 -> 176.34447 | F14: =Schedules!F8 -> 216.77259 | G14: =Schedules!G8 -> 221.90102 | H14: =Schedules!H8 -> 220 | I14: =Schedules!I8 -> 220 | J14: =Schedules!J8 -> 220 | ... L14: =Schedules!L8 -> 220
A15: Days Sales Outstanding (DSO) | B15: days | C15: =Schedules!C9 -> 7.1608389 | D15: =Schedules!D9 -> 6.063093 | E15: =Schedules!E9 -> 7.2737061 | F15: =Schedules!F9 -> 6.4479952 | G15: =Schedules!G9 -> 3.8173639 | H15: =Schedules!H9 -> 4 | I15: =Schedules!I9 -> 4 | J15: =Schedules!J9 -> 4 | ... L15: =Schedules!L9 -> 4
A16: Days Payables Outstanding (DPO) | B16: days | C16: =Schedules!C10 -> 21.824777 | D16: =Schedules!D10 -> 14.597595 | E16: =Schedules!E10 -> 13.051582 | F16: =Schedules!F10 -> 15.098091 | G16: =Schedules!G10 -> 14.868505 | H16: =Schedules!H10 -> 15 | I16: =Schedules!I10 -> 15 | J16: =Schedules!J10 -> 15 | ... L16: =Schedules!L10 -> 15
A17: Net Cash Conversion Cycle (DIO + DSO - DPO) | B17: days | C17: =C14+C15-C16 -> 214.86728 | D17: =D14+D15-D16 -> 190.87779 | E17: =E14+E15-E16 -> 170.56659 | F17: =F14+F15-F16 -> 208.12249 | G17: =G14+G15-G16 -> 210.84988 | H17: =H14+H15-H16 -> 209 | I17: =I14+I15-I16 -> 209 | J17: =J14+J15-J16 -> 209 | ... L17: =L14+L15-L16 -> 209
A19: 3. DUPONT 3-STAGE ROE DECOMPOSITION
A20: Net Profit Margin (PAT / Revenue) | B20: % | C20: =IS!C28 -> 0.076322095 | D20: =IS!D28 -> 0.08069008 | E20: =IS!E28 -> 0.068436301 | F20: =IS!F28 -> 0.055197168 | G20: =IS!G28 -> 0.057921538 | H20: =IS!H28 -> 0.056753518 | I20: =IS!I28 -> 0.058343486 | J20: =IS!J28 -> 0.060176437 | ... L20: =IS!L28 -> 0.06261478
A21: Asset Turnover (Revenue / Avg Total Assets) | B21: x | D21: =IS!D5/AVERAGE(BS!C19,BS!D19) -> 1.6830164 | E21: =IS!E5/AVERAGE(BS!D19,BS!E19) -> 1.7442849 | F21: =IS!F5/AVERAGE(BS!E19,BS!F19) -> 1.674751 | G21: =IS!G5/AVERAGE(BS!F19,BS!G19) -> 1.7307723 | H21: =IS!H5/AVERAGE(BS!G19,BS!H19) -> 1.5802948 | I21: =IS!I5/AVERAGE(BS!H19,BS!I19) -> 1.5788221 | J21: =IS!J5/AVERAGE(BS!I19,BS!J19) -> 1.5728429 | K21: =IS!K5/AVERAGE(BS!J19,BS!K19) -> 1.5709205 | L21: =IS!L5/AVERAGE(BS!K19,BS!L19) -> 1.5669731
A22: Financial Leverage Multiplier (Avg Total Assets / Avg Equity) | B22: x | D22: =AVERAGE(BS!C19,BS!D19)/AVERAGE(BS!C24,BS!D24) -> 2.2704243 | E22: =AVERAGE(BS!D19,BS!E19)/AVERAGE(BS!D24,BS!E24) -> 2.7502935 | F22: =AVERAGE(BS!E19,BS!F19)/AVERAGE(BS!E24,BS!F24) -> 3.4351715 | G22: =AVERAGE(BS!F19,BS!G19)/AVERAGE(BS!F24,BS!G24) -> 3.7035899 | H22: =AVERAGE(BS!G19,BS!H19)/AVERAGE(BS!G24,BS!H24) -> 3.6432038 | I22: =AVERAGE(BS!H19,BS!I19)/AVERAGE(BS!H24,BS!I24) -> 3.2910125 | J22: =AVERAGE(BS!I19,BS!J19)/AVERAGE(BS!I24,BS!J24) -> 2.9799682 | K22: =AVERAGE(BS!J19,BS!K19)/AVERAGE(BS!J24,BS!K24) -> 2.7136877 | L22: =AVERAGE(BS!K19,BS!L19)/AVERAGE(BS!K24,BS!L24) -> 2.4900446
A23: Decomposed ROE (Margin x Turnover x Leverage) | B23: % | D23: =D20*D21*D22 -> 0.3083298 | E23: =E20*E21*E22 -> 0.32830915 | F23: =F20*F21*F22 -> 0.31755246 | G23: =G20*G21*G22 -> 0.37128115 | H23: =H20*H21*H22 -> 0.32674907 | I23: =I20*I21*I22 -> 0.30314827 | J23: =J20*J21*J22 -> 0.28204826 | K23: =K20*K21*K22 -> 0.26169625 | L23: =L20*L21*L22 -> 0.24431241
A25: 4. BALANCE SHEET RESILIENCE & SOLVENCY METRICS
